Workbook

Sheet 📋 Raw Data
A1: # | B1: اسم الموظف | C1: الجنس | D1: القسم | E1: المسمى الوظيفي | F1: المدينة | G1: المؤهل | H1: سنوات الخبرة | I1: تقييم الأداء | J1: الراتب الأساسي (ج.م) | K1: بدل السكن (ج.م) | L1: بدل المواصلات (ج.م) | M1: المكافأة (ج.م) | N1: الراتب الإجمالي (ج.م) | O1: الضريبة (ج.م) | P1: صافي الراتب (ج.م)
A2: 1 | B2: مريم عمر | C2: أنثى | D2: العمليات | E2: مدير عمليات | F2: القاهرة | G2: بكالوريوس | H2: 12 | I2: ممتاز | J2: 23766 | K2: =J2*0.2 -> 4753.2 | L2: =500 -> 500 | M2: =J2*0.2 -> 4753.2 | N2: =J2+K2+L2+M2 -> 33772.4 | O2: =IF(N2>10000,N2*0.15,N2*0.1) -> 5065.86 | P2: =N2-O2 -> 28706.54
A3: 2 | B3: أحمد علي | C3: ذكر | D3: الموارد البشرية | E3: أخصائي توظيف | F3: القاهرة | G3: ماجستير | H3: 3 | I3: مقبول | J3: 9697 | K3: =J3*0.2 -> 1939.4 | L3: =500 -> 500 | M3: =J3*0 -> 0 | N3: =J3+K3+L3+M3 -> 12136.4 | O3: =IF(N3>10000,N3*0.15,N3*0.1) -> 1820.46 | P3: =N3-O3 -> 10315.94
A4: 3 | B4: خالد صالح | C4: ذكر | D4: المبيعات | E4: مشرف مبيعات | F4: أسيوط | G4: دكتوراه | H4: 2 | I4: جيد جداً | J4: 11377 | K4: =J4*0.2 -> 2275.4 | L4: =500 -> 500 | M4: =J4*0.12 -> 1365.24 | N4: =J4+K4+L4+M4 -> 15517.64 | O4: =IF(N4>10000,N4*0.15,N4*0.1) -> 2327.646 | P4: =N4-O4 -> 13189.994
A5: 4 | B5: عمر عمر | C5: ذكر | D5: التسويق | E5: مصمم جرافيك | F5: القاهرة | G5: دبلوم | H5: 18 | I5: جيد جداً | J5: 11331 | K5: =J5*0.2 -> 2266.2 | L5: =500 -> 500 | M5: =J5*0.12 -> 1359.72 | N5: =J5+K5+L5+M5 -> 15456.92 | O5: =IF(N5>10000,N5*0.15,N5*0.1) -> 2318.538 | P5: =N5-O5 -> 13138.382
A6: 5 | B6: يوسف علي | C6: ذكر | D6: المالية | E6: مدير مالي | F6: القاهرة | G6: بكالوريوس | H6: 20 | I6: جيد جداً | J6: 31542 | K6: =J6*0.2 -> 6308.4 | L6: =500 -> 500 | M6: =J6*0.12 -> 3785.04 | N6: =J6+K6+L6+M6 -> 42135.44 | O6: =IF(N6>10000,N6*0.15,N6*0.1) -> 6320.316 | P6: =N6-O6 -> 35815.124
A7: 6 | B7: رنا يوسف | C7: أنثى | D7: المالية | E7: محلل مالي | F7: الجيزة | G7: دبلوم | H7: 8 | I7: جيد جداً | J7: 17454 | K7: =J7*0.2 -> 3490.8 | L7: =500 -> 500 | M7: =J7*0.12 -> 2094.48 | N7: =J7+K7+L7+M7 -> 23539.28 | O7: =IF(N7>10000,N7*0.15,N7*0.1) -> 3530.892 | P7: =N7-O7 -> 20008.388
A8: 7 | B8: محمد صالح | C8: ذكر | D8: تقنية المعلومات | E8: مهندس شبكات | F8: المنصورة | G8: دبلوم | H8: 15 | I8: جيد | J8: 24622 | K8: =J8*0.2 -> 4924.4 | L8: =500 -> 500 | M8: =J8*0.06 -> 1477.32 | N8: =J8+K8+L8+M8 -> 31523.72 | O8: =IF(N8>10000,N8*0.15,N8*0.1) -> 4728.558 | P8: =N8-O8 -> 26795.162
A9: 8 | B9: محمد السيد | C9: ذكر | D9: الموارد البشرية | E9: مدير HR | F9: الجيزة | G9: ماجستير | H9: 16 | I9: مقبول | J9: 22818 | K9: =J9*0.2 -> 4563.6 | L9: =500 -> 500 | M9: =J9*0 -> 0 | N9: =J9+K9+L9+M9 -> 27881.6 | O9: =IF(N9>10000,N9*0.15,N9*0.1) -> 4182.24 | P9: =N9-O9 -> 23699.36
A10: 9 | B10: كريم صالح | C10: ذكر | D10: خدمة العملاء | E10: مشرف كول سنتر | F10: الجيزة | G10: دبلوم | H10: 20 | I10: مقبول | J10: 16093 | K10: =J10*0.2 -> 3218.6 | L10: =500 -> 500 | M10: =J10*0 -> 0 | N10: =J10+K10+L10+M10 -> 19811.6 | O10: =IF(N10>10000,N10*0.15,N10*0.1) -> 2971.74 | P10: =N10-O10 -> 16839.86
A11: 10 | B11: نورا علي | C11: أنثى | D11: تقنية المعلومات | E11: محلل بيانات | F11: القاهرة | G11: بكالوريوس | H11: 10 | I11: مقبول | J11: 17481 | K11: =J11*0.2 -> 3496.2 | L11: =500 -> 500 | M11: =J11*0 -> 0 | N11: =J11+K11+L11+M11 -> 21477.2 | O11: =IF(N11>10000,N11*0.15,N11*0.1) -> 3221.58 | P11: =N11-O11 -> 18255.62
A12: 11 | B12: رنا محمد | C12: أنثى | D12: الموارد البشرية | E12: أخصائي توظيف | F12: الإسكندرية | G12: بكالوريوس | H12: 16 | I12: ممتاز | J12: 12600 | K12: =J12*0.2 -> 2520 | L12: =500 -> 500 | M12: =J12*0.2 -> 2520 | N12: =J12+K12+L12+M12 -> 18140 | O12: =IF(N12>10000,N12*0.15,N12*0.1) -> 2721 | P12: =N12-O12 -> 15419
A13: 12 | B13: مريم عبدالله | C13: أنثى | D13: الموارد البشرية | E13: أخصائي توظيف | F13: المنصورة | G13: بكالوريوس | H13: 6 | I13: مقبول | J13: 11205 | K13: =J13*0.2 -> 2241 | L13: =500 -> 500 | M13: =J13*0 -> 0 | N13: =J13+K13+L13+M13 -> 13946 | O13: =IF(N13>10000,N13*0.15,N13*0.1) -> 2091.9 | P13: =N13-O13 -> 11854.1
A14: 13 | B14: مريم عمر | C14: أنثى | D14: خدمة العملاء | E14: مدير تجربة العميل | F14: الجيزة | G14: دكتوراه | H14: 12 | I14: مقبول | J14: 22606 | K14: =J14*0.2 -> 4521.2 | L14: =500 -> 500 | M14: =J14*0 -> 0 | N14: =J14+K14+L14+M14 -> 27627.2 | O14: =IF(N14>10000,N14*0.15,N14*0.1) -> 4144.08 | P14: =N14-O14 -> 23483.12
A15: 14 | B15: محمد إبراهيم | C15: ذكر | D15: التسويق | E15: مدير تسويق | F15: الإسكندرية | G15: بكالوريوس | H15: 16 | I15: جيد جداً | J15: 25494 | K15: =J15*0.2 -> 5098.8 | L15: =500 -> 500 | M15: =J15*0.12 -> 3059.28 | N15: =J15+K15+L15+M15 -> 34152.08 | O15: =IF(N15>10000,N15*0.15,N15*0.1) -> 5122.812 | P15: =N15-O15 -> 29029.268
A16: 15 | B16: علي عمر | C16: ذكر | D16: المالية | E16: محلل مالي | F16: أسيوط | G16: دبلوم | H16: 5 | I16: ممتاز | J16: 15618 | K16: =J16*0.2 -> 3123.6 | L16: =500 -> 500 | M16: =J16*0.2 -> 3123.6 | N16: =J16+K16+L16+M16 -> 22365.2 | O16: =IF(N16>10000,N16*0.15,N16*0.1) -> 3354.78 | P16: =N16-O16 -> 19010.42
A17: 16 | B17: ياسمين عمر | C17: أنثى | D17: الموارد البشرية | E17: مدير HR | F17: المنصورة | G17: دكتوراه | H17: 2 | I17: جيد جداً | J17: 18117 | K17: =J17*0.2 -> 3623.4 | L17: =500 -> 500 | M17: =J17*0.12 -> 2174.04 | N17: =J17+K17+L17+M17 -> 24414.44 | O17: =IF(N17>10000,N17*0.15,N17*0.1) -> 3662.166 | P17: =N17-O17 -> 20752.274
A18: 17 | B18: مصطفى إبراهيم | C18: ذكر | D18: المبيعات | E18: موظف مبيعات | F18: أسيوط | G18: بكالوريوس | H18: 4 | I18: ممتاز | J18: 8438 | K18: =J18*0.2 -> 1687.6 | L18: =500 -> 500 | M18: =J18*0.2 -> 1687.6 | N18: =J18+K18+L18+M18 -> 12313.2 | O18: =IF(N18>10000,N18*0.15,N18*0.1) -> 1846.98 | P18: =N18-O18 -> 10466.22
A19: 18 | B19: يوسف صالح | C19: ذكر | D19: المبيعات | E19: مدير مبيعات | F19: الإسكندرية | G19: دكتوراه | H19: 5 | I19: جيد | J19: 22550 | K19: =J19*0.2 -> 4510 | L19: =500 -> 500 | M19: =J19*0.06 -> 1353 | N19: =J19+K19+L19+M19 -> 28913 | O19: =IF(N19>10000,N19*0.15,N19*0.1) -> 4336.95 | P19: =N19-O19 -> 24576.05
A20: 19 | B20: منى علي | C20: أنثى | D20: المبيعات | E20: موظف مبيعات | F20: المنصورة | G20: دكتوراه | H20: 16 | I20: جيد | J20: 9123 | K20: =J20*0.2 -> 1824.6 | L20: =500 -> 500 | M20: =J20*0.06 -> 547.38 | N20: =J20+K20+L20+M20 -> 11994.98 | O20: =IF(N20>10000,N20*0.15,N20*0.1) -> 1799.247 | P20: =N20-O20 -> 10195.733
A21: 20 | B21: يوسف حسين | C21: ذكر | D21: الموارد البشرية | E21: مدير تدريب | F21: الإسكندرية | G21: بكالوريوس | H21: 7 | I21: جيد | J21: 13881 | K21: =J21*0.2 -> 2776.2 | L21: =500 -> 500 | M21: =J21*0.06 -> 832.86 | N21: =J21+K21+L21+M21 -> 17990.06 | O21: =IF(N21>10000,N21*0.15,N21*0.1) -> 2698.509 | P21: =N21-O21 -> 15291.551
A22: 21 | B22: كريم حسين | C22: ذكر | D22: العمليات | E22: مدير عمليات | F22: الجيزة | G22: دبلوم | H22: 6 | I22: جيد | J22: 20810 | K22: =J22*0.2 -> 4162 | L22: =500 -> 500 | M22: =J22*0.06 -> 1248.6 | N22: =J22+K22+L22+M22 -> 26720.6 | O22: =IF(N22>10000,N22*0.15,N22*0.1) -> 4008.09 | P22: =N22-O22 -> 22712.51
A23: 22 | B23: هبة صالح | C23: أنثى | D23: خدمة العملاء | E23: ممثل خدمة عملاء | F23: الإسكندرية | G23: دكتوراه | H23: 8 | I23: جيد جداً | J23: 7762 | K23: =J23*0.2 -> 1552.4 | L23: =500 -> 500 | M23: =J23*0.12 -> 931.44 | N23: =J23+K23+L23+M23 -> 10745.84 | O23: =IF(N23>10000,N23*0.15,N23*0.1) -> 1611.876 | P23: =N23-O23 -> 9133.964
A24: 23 | B24: سارة محمد | C24: أنثى | D24: خدمة العملاء | E24: مشرف كول سنتر | F24: المنصورة | G24: دبلوم | H24: 7 | I24: جيد | J24: 12688 | K24: =J24*0.2 -> 2537.6 | L24: =500 -> 500 | M24: =J24*0.06 -> 761.28 | N24: =J24+K24+L24+M24 -> 16486.88 | O24: =IF(N24>10000,N24*0.15,N24*0.1) -> 2473.032 | P24: =N24-O24 -> 14013.848
A25: 24 | B25: رنا علي | C25: أنثى | D25: التسويق | E25: مدير تسويق | F25: الإسكندرية | G25: دكتوراه | H25: 7 | I25: جيد | J25: 21685 | K25: =J25*0.2 -> 4337 | L25: =500 -> 500 | M25: =J25*0.06 -> 1301.1 | N25: =J25+K25+L25+M25 -> 27823.1 | O25: =IF(N25>10000,N25*0.15,N25*0.1) -> 4173.465 | P25: =N25-O25 -> 23649.635
A26: 25 | B26: مصطفى أحمد | C26: ذكر | D26: خدمة العملاء | E26: مدير تجربة العميل | F26: القاهرة | G26: بكالوريوس | H26: 13 | I26: جيد جداً | J26: 20553 | K26: =J26*0.2 -> 4110.6 | L26: =500 -> 500 | M26: =J26*0.12 -> 2466.36 | N26: =J26+K26+L26+M26 -> 27629.96 | O26: =IF(N26>10000,N26*0.15,N26*0.1) -> 4144.494 | P26: =N26-O26 -> 23485.466
A27: 26 | B27: حسن أحمد | C27: ذكر | D27: المبيعات | E27: مشرف مبيعات | F27: المنصورة | G27: دكتوراه | H27: 13 | I27: ممتاز | J27: 16348 | K27: =J27*0.2 -> 3269.6 | L27: =500 -> 500 | M27: =J27*0.2 -> 3269.6 | N27: =J27+K27+L27+M27 -> 23387.2 | O27: =IF(N27>10000,N27*0.15,N27*0.1) -> 3508.08 | P27: =N27-O27 -> 19879.12
A28: 27 | B28: علي محمد | C28: ذكر | D28: التسويق | E28: مصمم جرافيك | F28: المنصورة | G28: ماجستير | H28: 20 | I28: مقبول | J28: 13410 | K28: =J28*0.2 -> 2682 | L28: =500 -> 500 | M28: =J28*0 -> 0 | N28: =J28+K28+L28+M28 -> 16592 | O28: =IF(N28>10000,N28*0.15,N28*0.1) -> 2488.8 | P28: =N28-O28 -> 14103.2
A29: 28 | B29: مريم السيد | C29: أنثى | D29: المالية | E29: محاسب | F29: القاهرة | G29: بكالوريوس | H29: 4 | I29: جيد جداً | J29: 10891 | K29: =J29*0.2 -> 2178.2 | L29: =500 -> 500 | M29: =J29*0.12 -> 1306.92 | N29: =J29+K29+L29+M29 -> 14876.12 | O29: =IF(N29>10000,N29*0.15,N29*0.1) -> 2231.418 | P29: =N29-O29 -> 12644.702
A30: 29 | B30: خالد محمد | C30: ذكر | D30: تقنية المعلومات | E30: مطور برمجيات | F30: الجيزة | G30: ماجستير | H30: 19 | I30: جيد | J30: 29293 | K30: =J30*0.2 -> 5858.6 | L30: =500 -> 500 | M30: =J30*0.06 -> 1757.58 | N30: =J30+K30+L30+M30 -> 37409.18 | O30: =IF(N30>10000,N30*0.15,N30*0.1) -> 5611.377 | P30: =N30-O30 -> 31797.803
A31: 30 | B31: مريم محمد | C31: أنثى | D31: العمليات | E31: مشرف مستودع | F31: المنصورة | G31: دكتوراه | H31: 17 | I31: جيد جداً | J31: 12457 | K31: =J31*0.2 -> 2491.4 | L31: =500 -> 500 | M31: =J31*0.12 -> 1494.84 | N31: =J31+K31+L31+M31 -> 16943.24 | O31: =IF(N31>10000,N31*0.15,N31*0.1) -> 2541.486 | P31: =N31-O31 -> 14401.754
A32: 31 | B32: مصطفى إبراهيم | C32: ذكر | D32: المالية | E32: محاسب | F32: الإسكندرية | G32: ماجستير | H32: 5 | I32: مقبول | J32: 11603 | K32: =J32*0.2 -> 2320.6 | L32: =500 -> 500 | M32: =J32*0 -> 0 | N32: =J32+K32+L32+M32 -> 14423.6 | O32: =IF(N32>10000,N32*0.15,N32*0.1) -> 2163.54 | P32: =N32-O32 -> 12260.06
A33: 32 | B33: كريم محمد | C33: ذكر | D33: تقنية المعلومات | E33: مهندس شبكات | F33: أسيوط | G33: دكتوراه | H33: 4 | I33: ممتاز | J33: 18704 | K33: =J33*0.2 -> 3740.8 | L33: =500 -> 500 | M33: =J33*0.2 -> 3740.8 | N33: =J33+K33+L33+M33 -> 26685.6 | O33: =IF(N33>10000,N33*0.15,N33*0.1) -> 4002.84 | P33: =N33-O33 -> 22682.76
A34: 33 | B34: سارة علي | C34: أنثى | D34: المالية | E34: محلل مالي | F34: أسيوط | G34: بكالوريوس | H34: 3 | I34: مقبول | J34: 14564 | K34: =J34*0.2 -> 2912.8 | L34: =500 -> 500 | M34: =J34*0 -> 0 | N34: =J34+K34+L34+M34 -> 17976.8 | O34: =IF(N34>10000,N34*0.15,N34*0.1) -> 2696.52 | P34: =N34-O34 -> 15280.28
A35: 34 | B35: عمر يوسف | C35: ذكر | D35: المالية | E35: مدير مالي | F35: المنصورة | G35: ماجستير | H35: 17 | I35: جيد | J35: 33333 | K35: =J35*0.2 -> 6666.6 | L35: =500 -> 500 | M35: =J35*0.06 -> 1999.98 | N35: =J35+K35+L35+M35 -> 42499.58 | O35: =IF(N35>10000,N35*0.15,N35*0.1) -> 6374.937 | P35: =N35-O35 -> 36124.643
A36: 35 | B36: مصطفى إبراهيم | C36: ذكر | D36: الموارد البشرية | E36: مدير HR | F36: المنصورة | G36: دكتوراه | H36: 11 | I36: ممتاز | J36: 24751 | K36: =J36*0.2 -> 4950.2 | L36: =500 -> 500 | M36: =J36*0.2 -> 4950.2 | N36: =J36+K36+L36+M36 -> 35151.4 | O36: =IF(N36>10000,N36*0.15,N36*0.1) -> 5272.71 | P36: =N36-O36 -> 29878.69
A37: 36 | B37: نورا عبدالله | C37: أنثى | D37: العمليات | E37: مشرف مستودع | F37: القاهرة | G37: ماجستير | H37: 12 | I37: جيد جداً | J37: 10750 | K37: =J37*0.2 -> 2150 | L37: =500 -> 500 | M37: =J37*0.12 -> 1290 | N37: =J37+K37+L37+M37 -> 14690 | O37: =IF(N37>10000,N37*0.15,N37*0.1) -> 2203.5 | P37: =N37-O37 -> 12486.5
A38: 37 | B38: مصطفى عبدالله | C38: ذكر | D38: العمليات | E38: مدير عمليات | F38: المنصورة | G38: دكتوراه | H38: 6 | I38: جيد جداً | J38: 17905 | K38: =J38*0.2 -> 3581 | L38: =500 -> 500 | M38: =J38*0.12 -> 2148.6 | N38: =J38+K38+L38+M38 -> 24134.6 | O38: =IF(N38>10000,N38*0.15,N38*0.1) -> 3620.19 | P38: =N38-O38 -> 20514.41
A39: 38 | B39: أسماء عمر | C39: أنثى | D39: تقنية المعلومات | E39: محلل بيانات | F39: الإسكندرية | G39: دبلوم | H39: 11 | I39: ممتاز | J39: 19774 | K39: =J39*0.2 -> 3954.8 | L39: =500 -> 500 | M39: =J39*0.2 -> 3954.8 | N39: =J39+K39+L39+M39 -> 28183.6 | O39: =IF(N39>10000,N39*0.15,N39*0.1) -> 4227.54 | P39: =N39-O39 -> 23956.06
A40: 39 | B40: يوسف السيد | C40: ذكر | D40: الموارد البشرية | E40: أخصائي توظيف | F40: القاهرة | G40: دكتوراه | H40: 11 | I40: جيد | J40: 12542 | K40: =J40*0.2 -> 2508.4 | L40: =500 -> 500 | M40: =J40*0.06 -> 752.52 | N40: =J40+K40+L40+M40 -> 16302.92 | O40: =IF(N40>10000,N40*0.15,N40*0.1) -> 2445.438 | P40: =N40-O40 -> 13857.482
...

Sheet 📊 Dashboard
A1: 👥 لوحة تحليل رواتب الموظفين — 2025
A3: تحليل شامل لـ 200 موظف عبر 7 أقسام | الرواتب — الأداء — التوزيع الجغرافي
A5: 👤 إجمالي الموظفين | D5: 💰 إجمالي الرواتب | G5: 📊 متوسط صافي الراتب | J5: 🏆 أعلى راتب
A6: =COUNTA('📋 Raw Data'!B2:B201) -> 200 | D6: =SUM('📋 Raw Data'!N2:N201) -> 4426098.7 | G6: =AVERAGE('📋 Raw Data'!P2:P201) -> 18815.269 | J6: =MAX('📋 Raw Data'!N2:N201) -> 45473.6
A9: 🏢 تحليل الأقسام | F9: 🎯 توزيع تقييمات الأداء
A10: القسم | B10: عدد الموظفين | C10: متوسط الراتب الإجمالي | D10: إجمالي المكافآت | F10: التقييم | G10: عدد الموظفين | H10: متوسط الراتب | I10: إجمالي المكافآت
A11: المبيعات | B11: =COUNTIF('📋 Raw Data'!D$2:D$201,A11) -> 34 | C11: =AVERAGEIF('📋 Raw Data'!D$2:D$201,A11,'📋 Raw Data'!N$2:N$201) -> 18136.312 | D11: =SUMIF('📋 Raw Data'!D$2:D$201,A11,'📋 Raw Data'!M$2:M$201) -> 47590.2 | F11: ممتاز | G11: =COUNTIF('📋 Raw Data'!I$2:I$201,F11) -> 46 | H11: =AVERAGEIF('📋 Raw Data'!I$2:I$201,F11,'📋 Raw Data'!P$2:P$201) -> 20760.005 | I11: =SUMIF('📋 Raw Data'!I$2:I$201,F11,'📋 Raw Data'!M$2:M$201) -> 157211.8
A12: التسويق | B12: =COUNTIF('📋 Raw Data'!D$2:D$201,A12) -> 27 | C12: =AVERAGEIF('📋 Raw Data'!D$2:D$201,A12,'📋 Raw Data'!N$2:N$201) -> 22137.763 | D12: =SUMIF('📋 Raw Data'!D$2:D$201,A12,'📋 Raw Data'!M$2:M$201) -> 43817.6 | F12: جيد جداً | G12: =COUNTIF('📋 Raw Data'!I$2:I$201,F12) -> 58 | H12: =AVERAGEIF('📋 Raw Data'!I$2:I$201,F12,'📋 Raw Data'!P$2:P$201) -> 18591.65 | I12: =SUMIF('📋 Raw Data'!I$2:I$201,F12,'📋 Raw Data'!M$2:M$201) -> 112691.52
A13: تقنية المعلومات | B13: =COUNTIF('📋 Raw Data'!D$2:D$201,A13) -> 29 | C13: =AVERAGEIF('📋 Raw Data'!D$2:D$201,A13,'📋 Raw Data'!N$2:N$201) -> 28858.515 | D13: =SUMIF('📋 Raw Data'!D$2:D$201,A13,'📋 Raw Data'!M$2:M$201) -> 57021.34 | F13: جيد | G13: =COUNTIF('📋 Raw Data'!I$2:I$201,F13) -> 44 | H13: =AVERAGEIF('📋 Raw Data'!I$2:I$201,F13,'📋 Raw Data'!P$2:P$201) -> 20683.379 | I13: =SUMIF('📋 Raw Data'!I$2:I$201,F13,'📋 Raw Data'!M$2:M$201) -> 49936.62
A14: الموارد البشرية | B14: =COUNTIF('📋 Raw Data'!D$2:D$201,A14) -> 31 | C14: =AVERAGEIF('📋 Raw Data'!D$2:D$201,A14,'📋 Raw Data'!N$2:N$201) -> 22673.73 | D14: =SUMIF('📋 Raw Data'!D$2:D$201,A14,'📋 Raw Data'!M$2:M$201) -> 55020.42 | F14: مقبول | G14: =COUNTIF('📋 Raw Data'!I$2:I$201,F14) -> 52 | H14: =AVERAGEIF('📋 Raw Data'!I$2:I$201,F14,'📋 Raw Data'!P$2:P$201) -> 15763.637 | I14: =SUMIF('📋 Raw Data'!I$2:I$201,F14,'📋 Raw Data'!M$2:M$201) -> 0
A15: المالية | B15: =COUNTIF('📋 Raw Data'!D$2:D$201,A15) -> 23 | C15: =AVERAGEIF('📋 Raw Data'!D$2:D$201,A15,'📋 Raw Data'!N$2:N$201) -> 25563.984 | D15: =SUMIF('📋 Raw Data'!D$2:D$201,A15,'📋 Raw Data'!M$2:M$201) -> 45106.84
A16: العمليات | B16: =COUNTIF('📋 Raw Data'!D$2:D$201,A16) -> 31 | C16: =AVERAGEIF('📋 Raw Data'!D$2:D$201,A16,'📋 Raw Data'!N$2:N$201) -> 19089.085 | D16: =SUMIF('📋 Raw Data'!D$2:D$201,A16,'📋 Raw Data'!M$2:M$201) -> 32960.42
A17: خدمة العملاء | B17: =COUNTIF('📋 Raw Data'!D$2:D$201,A17) -> 25 | C17: =AVERAGEIF('📋 Raw Data'!D$2:D$201,A17,'📋 Raw Data'!N$2:N$201) -> 19689.149 | D17: =SUMIF('📋 Raw Data'!D$2:D$201,A17,'📋 Raw Data'!M$2:M$201) -> 38323.12
A20: ⚖️ تحليل الفجوة بين الجنسين | F20: 🌍 التوزيع الجغرافي
A21: الجنس | B21: عدد الموظفين | C21: متوسط الراتب الإجمالي | D21: متوسط سنوات الخبرة | F21: المدينة | G21: عدد الموظفين | H21: متوسط الراتب | I21: إجمالي الرواتب
A22: ذكر | B22: =COUNTIF('📋 Raw Data'!C$2:C$201,A22) -> 109 | C22: =AVERAGEIF('📋 Raw Data'!C$2:C$201,A22,'📋 Raw Data'!N$2:N$201) -> 22115.182 | D22: =AVERAGEIF('📋 Raw Data'!C$2:C$201,A22,'📋 Raw Data'!H$2:H$201) -> 9.5321101 | F22: القاهرة | G22: =COUNTIF('📋 Raw Data'!F$2:F$201,F22) -> 41 | H22: =AVERAGEIF('📋 Raw Data'!F$2:F$201,F22,'📋 Raw Data'!P$2:P$201) -> 19200.475 | I22: =SUMIF('📋 Raw Data'!F$2:F$201,F22,'📋 Raw Data'!N$2:N$201) -> 926140.58
A23: أنثى | B23: =COUNTIF('📋 Raw Data'!C$2:C$201,A23) -> 91 | C23: =AVERAGEIF('📋 Raw Data'!C$2:C$201,A23,'📋 Raw Data'!N$2:N$201) -> 22148.835 | D23: =AVERAGEIF('📋 Raw Data'!C$2:C$201,A23,'📋 Raw Data'!H$2:H$201) -> 9.9010989 | F23: الإسكندرية | G23: =COUNTIF('📋 Raw Data'!F$2:F$201,F23) -> 40 | H23: =AVERAGEIF('📋 Raw Data'!F$2:F$201,F23,'📋 Raw Data'!P$2:P$201) -> 19319.519 | I23: =SUMIF('📋 Raw Data'!F$2:F$201,F23,'📋 Raw Data'!N$2:N$201) -> 909153.82
F24: الجيزة | G24: =COUNTIF('📋 Raw Data'!F$2:F$201,F24) -> 44 | H24: =AVERAGEIF('📋 Raw Data'!F$2:F$201,F24,'📋 Raw Data'!P$2:P$201) -> 18119.848 | I24: =SUMIF('📋 Raw Data'!F$2:F$201,F24,'📋 Raw Data'!N$2:N$201) -> 937968.62
F25: المنصورة | G25: =COUNTIF('📋 Raw Data'!F$2:F$201,F25) -> 49 | H25: =AVERAGEIF('📋 Raw Data'!F$2:F$201,F25,'📋 Raw Data'!P$2:P$201) -> 18505.479 | I25: =SUMIF('📋 Raw Data'!F$2:F$201,F25,'📋 Raw Data'!N$2:N$201) -> 1066317.3
F26: أسيوط | G26: =COUNTIF('📋 Raw Data'!F$2:F$201,F26) -> 26 | H26: =AVERAGEIF('📋 Raw Data'!F$2:F$201,F26,'📋 Raw Data'!P$2:P$201) -> 19192.756 | I26: =SUMIF('📋 Raw Data'!F$2:F$201,F26,'📋 Raw Data'!N$2:N$201) -> 586518.44
